Workbook

Sheet Design Standards
B1: Design Standards
A2: Owner: | B2: Justin
A3: Channel (i.e. Public or Secure Web) | B3: Domain (i.e. OMCOZA, OMCOM) | C3: Area/Journey (i.e. Personal, Business) | D3: Cluster (i.e. L&S, Wealth, Bank) | E3: Deliverable / Task / Milestone | F3: Start Date | G3: End Date | H3: Effort (in days) | I3: Confidence level to complete it in the number of days assigned? | J3: Priority | K3: Are your deliverable dependent on an upstream team to complete their work before you can begin? | L3: What deliverable are you dependent on? | M3: Current deliverable / task Status | N3: Comments
A4: Public Web | B4: OMCOZA | C4: Entire site | D4: Navigation | E4: Design navigation structure based on the IA | F4: 46177 | G4: 46190 | H4: =NETWORKDAYS(F4,G4) -> 10 | I4: 1 | J4: Critical | K4: Yes | L4: Though we have an agreed structure, there is a dependency on brand alignment. Even though there is structure, we may not have stressed tested everything. | M4: In Progress | N4: This is about 90% complete, there is some changes based on testing and brand alignment (based on the approved interim brand). The DS team has paused this until we provide the amended nav structure.
A5: Public Web | B5: OMCOZA | C5: Entire site | D5: Navigation | E5: Complete footer navigation structure based on the IA | F5: 46177 | G5: 46190 | H5: =NETWORKDAYS(F5,G5) -> 10 | I5: 1 | J5: Critical | K5: Yes | L5: Structure is agreed, we just need to finalise it with the actual AI and Nav items to display. We also need to remove the ribbon logo and update it as per the interim brand. | M5: In Progress | N5: This is about 70% complete, just need to align to approved interim Brand CI
A6: Public Web | B6: OMCOZA | C6: Entire site | D6: Templates | E6: Design Landing Page Template | F6: 46191 | G6: 46204 | H6: =NETWORKDAYS(F6,G6) -> 10 | I6: 0.6 | J6: Critical | K6: Yes | L6: This requires input and alignment from who will be providing feedback and approval of templates like this. | M6: In Progress | N6: This work has started
A7: Public Web | B7: OMCOZA | C7: Entire site | D7: Templates | E7: Design Section Page Template | F7: 46191 | G7: 46204 | H7: =NETWORKDAYS(F7,G7) -> 10 | I7: 0.6 | J7: High | K7: Yes | L7: This requires input and alignment from who will be providing feedback and approval of templates like this. | M7: In Progress | N7: This work has started
A8: Public Web | B8: OMCOZA | C8: Entire site | D8: Templates | E8: Finalise Category Page Template | F8: 46177 | G8: 46190 | H8: =NETWORKDAYS(F8,G8) -> 10 | I8: 0.8 | J8: High | K8: Yes | L8: This needs to be further stress tested, but Retirement and Funeral is in a place where we are communicting this to DS. | M8: In Progress | N8: This is about 90% with the 2 categories designed.
A9: Public Web | B9: OMCOZA | C9: Entire site | D9: Templates | E9: Finalise Product Page Template | F9: 46177 | G9: 46190 | H9: =NETWORKDAYS(F9,G9) -> 10 | I9: 0.8 | J9: High | K9: Yes | L9: This needs to be further stress tested, but Max Investments, Funeral Plan and FlexiSave is in a place where we are communicting this to DS. | M9: In Progress | N9: This is about 90% done with 3 product pages completed.
A10: Public Web | B10: OMCOZA | C10: Entire site | D10: Templates | E10: Design Utility Template: Contact Us | F10: 46177 | G10: 46190 | H10: =NETWORKDAYS(F10,G10) -> 10 | I10: 0.8 | J10: High | K10: No | L10: We are simply consolidating the contact details into one page. | M10: In Progress | N10: The work has started for both desktop and mobile.
A11: Public Web | B11: OMCOZA | C11: Personal | D11: Templates | E11: Design Utility Template: All Calculators | F11: 46177 | G11: 46190 | H11: =NETWORKDAYS(F11,G11) -> 10 | I11: 0.4 | J11: High | K11: Yes | L11: There is alot of calculators that require alot of input across different product and business clusters. | M11: In Progress | N11: The work has started for both desktop and mobile.
A12: Public Web | B12: OMCOZA | C12: Personal | D12: Templates | E12: Design Utility Template: Calculators Page | F12: 46177 | G12: 46190 | H12: 10 | I12: 0.4 | J12: High | K12: Yes | L12: There needs to be alignment around skinning and improving the experience. This does require input from business, product and tech. | M12: In Progress | N12: This work has started.
A13: Public Web | B13: OMCOZA | C13: Entire site | D13: Tenant | E13: Design Tenant Template | F13: 46177 | G13: 46190 | H13: =NETWORKDAYS(F13,G13) -> 10 | I13: 0.7 | J13: High | K13: Yes | L13: This requires understanding of the tenants and what they need. So at the moment we can reference OM Bank and Rewards. | M13: In Progress
A14: Public Web | B14: OMCOZA | C14: Entire site | D14: Templates | E14: Design Utility Templates: About Us | F14: 46191 | G14: 46204 | H14: =NETWORKDAYS(F14,G14) -> 10 | I14: 0.6 | J14: Medium | K14: No | L14: We are using existing content, we just need to consider how to consolidate the content. | M14: Not Started
A15: Public Web | B15: OMCOZA | C15: Entire site | D15: Templates | E15: Design Utility Template: Careers | F15: 46191 | G15: 46204 | H15: =NETWORKDAYS(F15,G15) -> 10 | I15: 0.4 | J15: Medium | K15: Yes | L15: This may require input from HC but if we are migrating the content as is, then this could be a simple process. | M15: Not Started
A16: Secure Web | B16: MyOM | C16: Entire site | D16: Navigation | E16: Design navigation structure based on the IA | F16: 46205 | G16: 46218 | H16: =NETWORKDAYS(F16,G16) -> 10 | I16: 0.4 | J16: High | K16: Yes | L16: Initial designs have been done, it requires further discussion of how the pieces need to fit. | M16: In Progress | N16: Initial designs has started.
A17: Secure Web | B17: MyOM | C17: Entire site | D17: Navigation | E17: Design navigation solution to allow access to other secure sites | F17: 46205 | G17: 46218 | H17: =NETWORKDAYS(F17,G17) -> 10 | I17: 0.7 | J17: High | K17: Yes | M17: In Progress
B18: Old Mutual Design Standards | C18: Generic | D18: Copy | E18: Finalise generic copy standards | F18: 46177 | G18: 46190 | H18: =NETWORKDAYS(F18,G18) -> 10 | I18: 0.8 | J18: Critical | K18: Yes | L18: Alignment with Group Marketing | M18: Ready | N18: We are ready for sign off, it is aligned to brand and are requesting us to send to them for their records.
B19: Old Mutual Design Standards | C19: Generic | D19: Copy | E19: Finalise SEO + AIEO standards | F19: 46177 | G19: 46190 | H19: =NETWORKDAYS(F19,G19) -> 10 | I19: 0.8 | J19: Critical | K19: Yes | L19: Alignment with Group Marketing | M19: Ready | N19: SEO is also in progress with their own standards, so our standards will be a living process and document
B20: Old Mutual Design Standards | C20: Generic | D20: CI | E20: Align DS to iterim Brand CI | F20: 46177 | G20: 46204 | H20: =NETWORKDAYS(F20,G20) -> 20 | I20: 0.7 | J20: High | K20: Yes | L20: Alignment with Group Marketing | M20: In Progress | N20: The Interim Brand CI has been approved, luckily no major changes and just need align DS to brand.
A21: Public Web | B21: OMCOZA | C21: OM Bank | D21: Tenant | E21: Design OM Bank Tenant site (structure) | F21: 46190 | G21: 46205 | H21: 10 | I21: 0.2 | J21: Low | K21: Yes | L21: Alignment with OM Bank but also OMF | M21: Not Started | N21: We need to have initial conversations around OM Bank and if OMF falls under their domain which means they will need to design and build out their screens and IA.
A22: Public Web | B22: OMCOZA | C22: Rewards | D22: Tenant | E22: Design Rewards Tenant Site | F22: 46191 | G22: 46205 | H22: 10 | I22: 0.8 | J22: Low | K22: Yes | L22: Rewards is in progress with a redeisgn / revamp. So we will be using their existing structure and content. | M22: In Progress | N22: For the initial migration - we are keeping to their existing structure and content while they go through their redesign.
A23: Public Web | B23: OMCOZA | C23: Insure / iWyze | D23: Tenant | E23: Design iWyze Tenant Product Page Template | F23: 46177 | G23: 46190 | H23: =NETWORKDAYS(F23,G23) -> 10 | I23: 0.3 | J23: High | K23: Yes | L23: Alignment with OMF as well as the actual tenant. | M23: Not Started
H24: =NETWORKDAYS(F24,G24) -> 0
H25: =NETWORKDAYS(F25,G25) -> 0
H26: =NETWORKDAYS(F26,G26) -> 0
H27: =NETWORKDAYS(F27,G27) -> 0
H28: =NETWORKDAYS(F28,G28) -> 0
H29: =NETWORKDAYS(F29,G29) -> 0
H30: =NETWORKDAYS(F30,G30) -> 0
H31: =NETWORKDAYS(F31,G31) -> 0
H32: =NETWORKDAYS(F32,G32) -> 0
H33: =NETWORKDAYS(F33,G33) -> 0
H34: =NETWORKDAYS(F34,G34) -> 0
H35: =NETWORKDAYS(F35,G35) -> 0
... H143: =NETWORKDAYS(F143,G143) -> 0

Sheet Design Delivery
A1: Workstream: | B1: Design Delivery
A2: Owner:
A3: Channel (i.e. Public or Secure Web) | B3: Domain (i.e. OMCOZA, OMCOM) | C3: Area/Journey (i.e. Personal, Business) | D3: Cluster (i.e. L&S, Wealth, Bank) | E3: Deliverable / Task / Milestone | F3: Start Date | G3: End Date | H3: Effort (in days) | I3: Confidence level to complete it in the number of days assigned? | J3: Priority | K3: Are your deliverable dependent on an upstream team to complete their work before you can begin? | L3: What deliverable are you dependent on? | M3: Current deliverable / task Status | N3: Comments
A4: Public Web | B4: OMCOZA | C4: Personal | D4: Retirement | E4: L3+ IA finalisation URL mapping (Current vs. New URL mapping (Current pages > New IA pages). outlining consolidated sections and pages that will be removed in the new Information Architecture. Category landing pages (5+) with enhanced copy Product landing pages (5+) with enhanced copy | F4: 46177 | G4: 46181 | H4: =NETWORKDAYS(F4,G4) -> 3 | I4: 1 | J4: Critical | K4: Yes | L4: We need stakeholder sessions in diaries already locked in for the the programme duration. Sign-off process defined. | M4: In Progress | N4: Dependencies * Stakeholder socialisation and buy-in: Must be completed prior to engagement commencing. * Active stakeholder participation is required throughout: As extended team members and thinking partners, not passive reviewers. * A clearly defined sign-off process: Must be in place before work begins. Risks * SEO standards not finalised: SEO governance is still being developed. Content decisions may need to be revisited as standards are finalised, making this a living document process rather than a single sign-off. * Tenant hierarchy misalignment: Some clusters (e.g. OM Insure) have not yet aligned to sharing a platform / real estate with internal tenant brands (e.g. iWyze). This has the potential to create structural conflict in our section and category templates and may require additional stakeholder resolution time. * Scope creep: Timelines are based on an agreed list of sites (OMCOZA, OMCOM, Bula Tsela, and LTD) and agreed scope. Any additional sites or out-of-scope requests will require a formal timeline and resource extension. Web and My Old Mutual (Secure): Unfamiliar territory - Additional timeshas been allocated to them, however, we have a number of unknowns in those two streams.
A5: Public Web | B5: OMCOZA | C5: Personal | D5: Funeral | E5: L3+ IA finalisation URL mapping (Current vs. New URL mapping (Current pages > New IA pages). outlining consolidated sections and pages that will be removed in the new Information Architecture. Category landing pages (5+) with enhanced copy Product landing pages (5+) with enhanced copy | F5: 46183 | G5: 46188 | H5: =NETWORKDAYS(F5,G5) -> 4 | I5: 1 | J5: Critical | K5: Yes | L5: We need Stakeholder sessions in diaries already locked in for the July Start. Sign-off process defined. | M5: In Progress
A6: Public Web | B6: OMCOZA | C6: Personal | D6: Investment > Flexi Save | E6: L3+ IA finalisation URL mapping (Current vs. New URL mapping (Current pages > New IA pages). outlining consolidated sections and pages that will be removed in the new Information Architecture. Product landing page with enhanced copy | F6: 46189 | G6: 46189 | H6: =NETWORKDAYS(F6,G6) -> 1 | I6: 1 | J6: Critical | K6: Yes | L6: We need Stakeholder sessions in diaries already locked in for the July Start. Sign-off process defined. | M6: In Progress
A7: Public Web | B7: OMCOZA | C7: Personal | D7: Entire Site | E7: Information Architecture Stakeholder Socialisation & Sign Off (L1 - L3) | F7: 46192 | G7: 46196 | H7: =NETWORKDAYS(F7,G7) -> 3 | I7: 0.8 | J7: Critical | K7: Yes | L7: We need Stakeholder sessions in diaries already locked in for the July Start. Sign-off process defined. | M7: In Progress
A8: Public Web | B8: OMCOZA | C8: Business | D8: Entire Site | E8: Information Architecture Stakeholder Socialisation & Sign Off (L1 - L3) | F8: 46192 | G8: 46196 | H8: =NETWORKDAYS(F8,G8) -> 3 | I8: 0.8 | J8: Critical | K8: Yes | L8: We need Stakeholder sessions in diaries already locked in for the July Start. Sign-off process defined. | M8: In Progress
A9: Public Web | B9: OMCOZA | C9: Corporate | D9: Entire Site | E9: Information Architecture Stakeholder Socialisation & Sign Off (L1 - L3) | F9: 46197 | G9: 46199 | H9: =NETWORKDAYS(F9,G9) -> 3 | I9: 0.8 | J9: Critical | K9: Yes | L9: We need Stakeholder sessions in diaries already locked in for the July Start. Sign-off process defined. | M9: In Progress
A10: Public Web | B10: OMCOZA | C10: Wealth | D10: Entire Site | E10: Information Architecture Stakeholder Socialisation & Sign Off (L1 - L3) | F10: 46202 | G10: 46206 | H10: =NETWORKDAYS(F10,G10) -> 5 | I10: 0.8 | J10: Critical | K10: Yes | L10: We need Stakeholder sessions in diaries already locked in for the July Start. Sign-off process defined. | M10: In Progress
A11: Public Web | B11: RESOURCE RECRUITMENT | C11: ALL SITES IN SCOPE | D11: ALL SITES IN SCOPE | E11: Kick-of recruitment process for additional capacity Vendor briefing CV review Interviews Candidate selection Onboarding | F11: 46181 | G11: 46203 | H11: =NETWORKDAYS(F11,G11) -> 17 | I11: 1 | J11: Critical | K11: No | M11: Not Started
A12: Public Web | B12: OMCOZA | C12: Personal | D12: Personal Landing | E12: Audience landing with enhanced copy | F12: 46209 | G12: 46211 | H12: =NETWORKDAYS(F12,G12) -> 3 | I12: 1 | J12: Critical | K12: Yes | L12: We need Stakeholder sessions in diaries already locked in for the July Start. Sign-off process defined. | M12: In Progress
A13: Public Web | B13: OMCOZA | C13: Personal | D13: Invest | E13: L3+ IA finalisation URL mapping (Current vs. New URL mapping (Current pages > New IA pages). outlining consolidated sections and pages that will be removed in the new Information Architecture. Section landing with enhanced copy Category landing pages (5+) with enhanced copy Product landing pages (5+) with enhanced copy | F13: 46209 | G13: 46218 | H13: =NETWORKDAYS(F13,G13) -> 8 | I13: 1 | J13: Critical | K13: Yes | L13: We need Stakeholder sessions in diaries already locked in for the July Start. Sign-off process defined. | M13: in Progress
A14: Public Web | B14: OMCOZA | C14: Personal | D14: OM BAnk | E14: L3+ IA finalisation Section landing with enhanced copy Product landing pages (5+) with enhanced copy | F14: 46219 | G14: 46223 | H14: =NETWORKDAYS(F14,G14) -> 3 | I14: 1 | J14: Critical | K14: Yes | L14: We need Stakeholder sessions in diaries already locked in for the July Start. Sign-off process defined. | M14: In Progress
A15: Public Web | B15: OMCOZA | C15: Personal | D15: Insure | E15: L3+ IA finalisation URL mapping (Current vs. New URL mapping (Current pages > New IA pages). outlining consolidated sections and pages that will be removed in the new Information Architecture. Section landing with enhanced copy Category landing pages (5+) with enhanced copy Product landing pages (5+) with enhanced copy | F15: 46224 | G15: 46237 | H15: =NETWORKDAYS(F15,G15) -> 10 | I15: 1 | J15: Critical | K15: Yes | L15: We need Stakeholder sessions in diaries already locked in for the July Start. Sign-off process defined. | M15: In Progress
A16: Public Web | B16: OMCOZA | C16: Personal | D16: About us | E16: L3+ IA finalisation URL mapping (Current vs. New URL mapping (Current pages > New IA pages). outlining consolidated sections and pages that will be removed in the new Information Architecture. Section landing with enhanced copy Category landing pages (3+) with enhanced copy Product landing pages (3+) with enhanced copy | F16: 46238 | G16: 46241 | H16: =NETWORKDAYS(F16,G16) -> 4 | I16: 1 | J16: Critical | K16: Yes | L16: We need Stakeholder sessions in diaries already locked in for the July Start. Sign-off process defined. | M16: In Progress
A17: Public Web | B17: OMCOZA | C17: Personal | D17: Careers | E17: L3+ IA finalisation URL mapping (Current vs. New URL mapping (Current pages > New IA pages). outlining consolidated sections and pages that will be removed in the new Information Architecture. Section landing with enhanced copy Category landing pages (3+) with enhanced copy Product landing pages (3+) with enhanced copy | F17: 46244 | G17: 46247 | H17: =NETWORKDAYS(F17,G17) -> 4 | I17: 1 | J17: Critical | K17: Yes | L17: We need Stakeholder sessions in diaries already locked in for the July Start. Sign-off process defined. | M17: In Progress
A18: Public Web | B18: OMCOM | C18: Entire site | D18: Entire site | E18: Mapping of new IA and Footer to sxisting site structure | F18: 46248 | G18: 46251 | H18: =NETWORKDAYS(F18,G18) -> 2 | I18: 1 | J18: Critical | K18: Yes | L18: We need Stakeholder sessions in diaries already locked in for the July Start. Sign-off process defined. | M18: In Progress
A19: Public Web | B19: Bula Tsela | C19: Entire site | D19: Entire site | E19: Mapping of new IA and Footer to sxisting site structure | F19: 46252 | G19: 46253 | H19: =NETWORKDAYS(F19,G19) -> 2 | I19: 1 | J19: Critical | K19: Yes | L19: We need Stakeholder sessions in diaries already locked in for the July Start. Sign-off process defined. | M19: In Progress
A20: Public Web | B20: Learn Think Do (LTD) | C20: Entire site | D20: Entire site | E20: Mapping of new IA and Footer to sxisting site structure | F20: 46254 | G20: 46255 | H20: =NETWORKDAYS(F20,G20) -> 2 | I20: 1 | J20: Critical | K20: Yes | L20: We need Stakeholder sessions in diaries already locked in for the July Start. Sign-off process defined. | M20: In Progress
A21: Public Web | B21: OMCOZA | C21: Wealth | D21: Wealth Landing | E21: Audience landing with enhanced copy | F21: 46209 | G21: 46213 | H21: =NETWORKDAYS(F21,G21) -> 5 | I21: 0.7 | J21: Critical | K21: Yes | L21: We need Stakeholder sessions in diaries already locked in for the July Start. Sign-off process defined. | M21: In Progress
A22: Public Web | B22: OMCOZA | C22: Wealth | D22: Invest | E22: L3+ IA finalisation URL mapping (Current vs. New URL mapping (Current pages > New IA pages). outlining consolidated sections and pages that will be removed in the new Information Architecture. Section landing with enhanced copy Category landing pages (5+) with enhanced copy Product landing pages (5+) with enhanced copy | F22: 46216 | G22: 46234 | H22: =NETWORKDAYS(F22,G22) -> 15 | I22: 0.7 | J22: Critical | K22: Yes | L22: We need Stakeholder sessions in diaries already locked in for the July Start. Sign-off process defined. | M22: In Progress
A23: Public Web | B23: OMCOZA | C23: Wealth | D23: Plan | E23: L3+ IA finalisation URL mapping (Current vs. New URL mapping (Current pages > New IA pages). outlining consolidated sections and pages that will be removed in the new Information Architecture. Section landing with enhanced copy Category landing pages (5+) with enhanced copy Product landing pages (5+) with enhanced copy | F23: 46237 | G23: 46255 | H23: =NETWORKDAYS(F23,G23) -> 15 | I23: 0.7 | J23: Critical | K23: Yes | L23: We need Stakeholder sessions in diaries already locked in for the July Start. Sign-off process defined. | M23: In Progress
... A35: Public Web | B35: OMCOZA | C35: Business | D35: Tools | E35: L3+ IA finalisation URL mapping (Current vs. New URL mapping (Current pages > New IA pages). outlining consolidated sections and pages that will be removed in the new Information Architecture. Section landing with enhanced copy Category landing pages (5+) with enhanced copy Product landing pages (5+) with enhanced copy | F35: 46253 | G35: 46262 | H35: =NETWORKDAYS(F35,G35) -> 8 | I35: 1 | J35: Critical | K35: Yes | L35: We need Stakeholder sessions in diaries already locked in for the July Start. Sign-off process defined. | M35: In Progress
A36: Public Web | B36: OMCOZA | C36: Personal | D36: My OldMutual | E36: Public > Secure | Secure > Public Transition. Access to other secure sites. Service tree definition (E.g. Product > Payment or Payment Hub > Product selection). IA + Navigation flow (Primary noun architecture). Potential Template impact (E.g. Dashboard). Customer validation. | F36: 46209 | G36: 46276 | H36: =NETWORKDAYS(F36,G36) -> 50 | I36: 0.7 | J36: Critical | K36: Yes | L36: We need Stakeholder sessions in diaries already locked in for the July Start. Sign-off process defined.
A37: Public Web | B37: OMAR: Kenya | C37: Entire Site | D37: Entire Site | E37: Socilaisation of defined IA and Page templates for handover. | F37: 46254 | G37: 46258 | H37: =NETWORKDAYS(F37,G37) -> 3 | I37: 1 | J37: High | K37: Yes | L37: We need Stakeholder sessions in diaries already locked in for the July Start. Sign-off process defined. | M37: In Progress
A38: Public Web | B38: OMAR: Zimbabwe | C38: Entire Site | D38: Entire Site | E38: Socilaisation of defined IA and Page templates for handover. | F38: 46254 | G38: 46258 | H38: =NETWORKDAYS(F38,G38) -> 3 | I38: 1 | J38: High | K38: Yes | L38: We need Stakeholder sessions in diaries already locked in for the July Start. Sign-off process defined. | M38: In Progress
H39: =NETWORKDAYS(F39,G39) -> 0
H40: =NETWORKDAYS(F40,G40) -> 0
H41: =NETWORKDAYS(F41,G41) -> 0
H42: =NETWORKDAYS(F42,G42) -> 0
H43: =NETWORKDAYS(F43,G43) -> 0
H44: =NETWORKDAYS(F44,G44) -> 0
H45: =NETWORKDAYS(F45,G45) -> 0
H46: =NETWORKDAYS(F46,G46) -> 0
H47: =NETWORKDAYS(F47,G47) -> 0
H48: =NETWORKDAYS(F48,G48) -> 0
H49: =NETWORKDAYS(F49,G49) -> 0
H50: =NETWORKDAYS(F50,G50) -> 0
... H149: =NETWORKDAYS(F149,G149) -> 0

Sheet Content Readiness
A1: Workstream: | B1: Content Readiness
A2: Owner: | B2: Natalie Patel
A3: Channel (i.e. Public or Secure Web) | B3: Domain (i.e. OMCOZA, OMCOM) | C3: Area/Journey (i.e. Personal, Business) | D3: Cluster (i.e. L&S, Wealth, Bank) | E3: Deliverable / Task / Milestone | F3: Start Date | G3: End Date | H3: Effort (in days) | I3: Confidence level to complete it in the number of days assigned? | J3: Priority | K3: Are your deliverable dependent on an upstream team to complete their work before you can begin? | L3: What deliverable are you dependent on? | M3: Current deliverable / task Status | N3: Comments
A4: Public Web | B4: OMCOZA | C4: Personal | D4: Retirement | E4: Copy enhancement + link mapping dependent on design activities | F4: 46177 | G4: 46181 | H4: =NETWORKDAYS(F4,G4) -> 3 | I4: 0.8 | J4: Critical | K4: Yes | L4: Design readiness | M4: In Progress
A5: Public Web | B5: OMCOZA | C5: Personal | D5: Funeral | E5: Copy enhancement + link mapping dependent on design activities | F5: 46183 | G5: 46188 | H5: =NETWORKDAYS(F5,G5) -> 4 | I5: 0.8 | J5: Critical | K5: Yes | L5: Design readiness | M5: In Progress
A6: Public Web | B6: OMCOZA | C6: Personal | D6: Invest Flexi Save | E6: Copy enhancement + link mapping dependent on design activities | F6: 46189 | G6: 46190 | H6: =NETWORKDAYS(F6,G6) -> 2 | I6: 0.8 | J6: Critical | K6: Yes | L6: Design readiness | M6: In Progress
A7: Public Web | B7: OMCOZA | C7: Personal | D7: Personal landing page | E7: Copy enhancement + link mapping dependent on design activities | F7: 46209 | G7: 46211 | H7: =NETWORKDAYS(F7,G7) -> 3 | I7: 1 | J7: Critical | K7: Yes | L7: Design readiness | M7: In Progress
A8: Public Web | B8: OMCOZA | H8: =NETWORKDAYS(F8,G8) -> 0
A9: Public Web | B9: OMCOZA | H9: =NETWORKDAYS(F9,G9) -> 0
A10: Public Web | B10: OMCOZA | H10: =NETWORKDAYS(F10,G10) -> 0
A11: Public Web | B11: OMCOZA | H11: =NETWORKDAYS(F11,G11) -> 0
A12: Public Web | B12: OMCOZA | H12: =NETWORKDAYS(F12,G12) -> 0
A13: Public Web | B13: OMCOZA | H13: =NETWORKDAYS(F13,G13) -> 0
H14: =NETWORKDAYS(F14,G14) -> 0
H15: =NETWORKDAYS(F15,G15) -> 0
H16: =NETWORKDAYS(F16,G16) -> 0
H17: =NETWORKDAYS(F17,G17) -> 0
H18: =NETWORKDAYS(F18,G18) -> 0
H19: =NETWORKDAYS(F19,G19) -> 0
H20: =NETWORKDAYS(F20,G20) -> 0
H21: =NETWORKDAYS(F21,G21) -> 0
H22: =NETWORKDAYS(F22,G22) -> 0
H23: =NETWORKDAYS(F23,G23) -> 0
H24: =NETWORKDAYS(F24,G24) -> 0
H25: =NETWORKDAYS(F25,G25) -> 0
... H140: =NETWORKDAYS(F140,G140) -> 0

Sheet Feature Delivery
A1: Workstream: | B1: Feature Delivery
A2: Owner: | B2: Wayne & Tebogo
A3: Channel (i.e. Public or Secure Web) | B3: Domain (i.e. OMCOZA, OMCOM) | C3: Area/Journey (i.e. Personal, Business) | D3: Cluster (i.e. L&S, Wealth, Bank) | E3: Deliverable / Task / Milestone | F3: Start Date | G3: End Date | H3: Effort (in days) | I3: Confidence level to complete it in the number of days assigned? | J3: Priority | K3: Are your deliverable dependent on an upstream team to complete their work before you can begin? | L3: What deliverable are you dependent on? | M3: Current deliverable / task Status | N3: Comments
A4: Secure Web | B4: N/A | C4: Dashboard Views ( Porffolio Views) | D4: All | E4: Portfolio View | F4: TBC | G4: TBC | H4: TBC | I4: 0.1 | J4: High | K4: Yes | L4: Part of the design work that is underway - not included in the number of journeys currently tracked | M4: In Progress | N4: The dedicated Servicing team has limited availability, with three resources only confirmed until 10 September and one QE rolling off in August. This creates a significant delivery risk, as all required work must be completed
C5: Dashboard Views ( Porffolio Views) | D5: All | E5: Standards on how to creates views on dashboard | F5: TBC | G5: TBC | H5: TBC | I5: 0.1 | J5: High
A6: Secure Web | B6: N/A | C6: Servicing Transaction in Sec Web | D6: All | E6: Content Updates | F6: TBC | G6: TBC | H6: TBC | I6: 0.1 | J6: High | K6: Yes | L6: Content Updates to be confirmed | M6: Blocked | N6: .
A7: Secure Web | B7: N/A | C7: Servicing Transaction in Sec Web | D7: All | E7: Journeys Optimization | F7: TBC | G7: TBC | H7: TBC | I7: 0.1 | J7: High | K7: Yes | L7: Journey Optimisation to be confirmed | M7: Blocked | N7: .
A8: Public Web | B8: OMCOZA | C8: Personal | D8: L&S | E8: Funeral and Death Claims | F8: 46174 | G8: 46234 | H8: =NETWORKDAYS(F8,G8) -> 45 | I8: 0.8 | J8: High | K8: No | M8: In Progress
A9: Secure Web | B9: N/A | C9: Servicing Transaction in Sec Web | D9: All | E9: Transaction Tracking | F9: 46143 | G9: 46203 | H9: =NETWORKDAYS(F9,G9) -> 43 | I9: 0.8 | J9: High | K9: No | M9: In Progress
A10: Secure Web | B10: N/A | C10: Servicing Transaction in Sec Web | D10: All | E10: Lump Sum Injections | F10: 46082 | G10: 46203 | H10: =NETWORKDAYS(F10,G10) -> 87 | I10: 0.8 | J10: High | K10: No | M10: In Progress
A11: Secure Web | B11: N/A | C11: Servicing Transaction in Sec Web | D11: All | E11: Change Personal Details | F11: 46143 | G11: 46234 | H11: =NETWORKDAYS(F11,G11) -> 66 | I11: 0.8 | J11: High | K11: No | M11: In Progress
A12: Secure Web | B12: N/A | C12: Servicing Transaction in Sec Web | D12: All | E12: Manage Contributions | F12: 46143 | G12: 46203 | H12: 43 | I12: 0.8 | J12: High | K12: No | M12: In Progress
A13: Secure Web | B13: N/A | C13: Servicing Transaction in Sec Web | D13: All | E13: Switch Funds | F13: 46143 | G13: 46203 | H13: 43 | I13: 0.8 | J13: High | K13: No | M13: In Progress
A14: Secure Web | B14: N/A | C14: Servicing Transaction in Sec Web | D14: All | E14: Withdrawals/Disinvestments | F14: 46204 | G14: 46357 | H14: =NETWORKDAYS(F14,G14) -> 110 | I14: 0.4 | J14: High | K14: No | M14: In Progress
A15: Secure Web | B15: N/A | C15: Servicing Transaction in Sec Web | D15: All | E15: Change Premium Allocation | F15: 46082 | G15: 46203 | H15: =NETWORKDAYS(F15,G15) -> 87 | I15: 0.8 | J15: High | K15: No | M15: In Progress
A16: Public Web | B16: OMCOZA | C16: Personal | D16: L&S | E16: Easy Plus Sales Jorurney on Public Web | F16: TBC | G16: TBC | H16: 0 | I16: 0.1 | J16: High | K16: Yes | L16: product page has to be updated before this journey can be migrated | M16: Blocked | N16: .
A17: Public Web | B17: OMCOZA | C17: Personal | D17: L&S | E17: 2 Pot | F17: 46082 | G17: 46203 | H17: =NETWORKDAYS(F17,G17) -> 87 | I17: 0.8 | J17: High | M17: In Progress
A18: Public Web | B18: OMCOZA | C18: Personal | D18: L&S | E18: Find Advisor | F18: Beta Testing Ready | G18: Beta Testing Ready | H18: Beta Testing Ready | I18: 0.9 | J18: High | K18: Yes | L18: Design - Impact of of new templates on Find Advisor flow | M18: In Progress | N18: TBC
A19: Public Web | B19: OMCOZA | C19: Personal | D19: L&S | E19: Debt Calculator | F19: 46082 | G19: 46203 | H19: =NETWORKDAYS(F19,G19) -> 87 | I19: 0.8 | J19: High | K19: No | L19: BA Capacity is constrained due current BA on medical Leave | M19: In Progress
A20: Public Web | B20: OMCOZA | C20: Personal | D20: L&S | E20: Personal Calculator | F20: 46082 | G20: 46203 | H20: =NETWORKDAYS(F20,G20) -> 87 | I20: 0.8 | J20: High | K20: No | L20: End of Curent PI front end Development resources will move out of cross channel
A21: Public Web | B21: OMCOZA | C21: Personal | D21: L&S | E21: Budget Calculator | F21: 46083 | G21: 46203 | H21: =NETWORKDAYS(F21,G21) -> 87 | J21: High | K21: No
A22: Public Web | B22: OMCOZA | C22: Personal | D22: L&S | E22: Income Tax Calculator | F22: Beta Testing Ready | G22: Beta Testing Ready | H22: Beta Testing Ready | I22: 0.9 | J22: High | K22: No
A23: Public Web | B23: OMCOZA | C23: Personal | D23: L&S | E23: Retirement Calculator | F23: Beta Testing Ready | G23: Beta Testing Ready | H23: Beta Testing Ready | I23: 0.9 | J23: High | K23: No
A24: Public Web | B24: OMCOZA | C24: Personal | D24: L&S | E24: 2 Pot Calculator | F24: Beta Testing Ready | G24: Beta Testing Ready | H24: Beta Testing Ready | I24: 0.9 | J24: High | K24: No
A25: Public Web | B25: OMCOZA | C25: Personal | D25: L&S | E25: Contact Us | F25: Analysis in Progress | G25: Analysis in Progress | H25: Analysis in Progress | I25: 0.3 | J25: High | K25: No
H26: =NETWORKDAYS(F26,G26) -> 0
H27: =NETWORKDAYS(F27,G27) -> 0
H28: =NETWORKDAYS(F28,G28) -> 0
H29: =NETWORKDAYS(F29,G29) -> 0
H30: =NETWORKDAYS(F30,G30) -> 0
H31: =NETWORKDAYS(F31,G31) -> 0
H32: =NETWORKDAYS(F32,G32) -> 0
H33: =NETWORKDAYS(F33,G33) -> 0
H34: =NETWORKDAYS(F34,G34) -> 0
H35: =NETWORKDAYS(F35,G35) -> 0
H36: =NETWORKDAYS(F36,G36) -> 0
H37: =NETWORKDAYS(F37,G37) -> 0
... H140: =NETWORKDAYS(F140,G140) -> 0

Sheet Design Systems
A1: Workstream: | B1: Design Systems
A2: Owner: | B2: Brent van Zitters
A3: Channel (i.e. Public or Secure Web) | B3: Domain (i.e. OMCOZA, OMCOM) | C3: Area/Journey (i.e. Personal, Business) | D3: Cluster (i.e. L&S, Wealth, Bank) | E3: Deliverable / Task / Milestone | F3: Start Date | G3: End Date | H3: Effort (in days) | I3: Confidence level to complete it in the number of days assigned? | J3: Priority | K3: Are your deliverable dependent on an upstream team to complete their work before you can begin? | L3: What deliverable are you dependent on? | M3: Current deliverable / task Status | N3: Comments
A4: Public Web | B4: All | C4: All | D4: All | E4: Design and Develop CI Updates onto OMDSv2 | F4: As soon as received | H4: 10 | I4: 0.5 | J4: High | K4: Yes | L4: Foundational elements from Design Delivery | M4: Blocked
A5: Public Web | B5: All | C5: All | D5: All | E5: Design and Develop Top Navigation Component Updates | F5: 46143 | H5: 20 | I5: 0.5 | J5: Critical | K5: Yes | L5: Foundational elements from Design Delivery | M5: In Progress | N5: Started, but had to pause due to rework upstream.
A6: Secure Web | B6: All | C6: All | D6: All | E6: Design and Develop Top Navigation Component Updates | F6: As soon as received | H6: 20 | I6: 0.5 | J6: Critical | K6: Yes | L6: Foundational elements from Design Delivery | M6: Not Started
A7: Public Web | B7: All | C7: All | D7: All | E7: Design and Develop Footer Component Updates | F7: As soon as received | H7: 5 | I7: 0.5 | J7: Critical | K7: Yes | L7: Foundational elements from Design Delivery | M7: Not Started
A8: Public Web | B8: All | C8: All | D8: All | E8: Design and Develop Card Component Updates | F8: As soon as received | H8: 10 | I8: 0.5 | J8: Medium | K8: Yes | L8: Foundational elements from Design Delivery | M8: Not Started
A9: Public Web | B9: All | C9: All | D9: All | E9: Design and Develop Category Page Template | F9: As soon as received | H9: 8 | I9: 0.5 | J9: High | K9: Yes | L9: Foundational elements from Design Delivery | M9: Not Started
A10: Public Web | B10: All | C10: All | D10: All | E10: Design and Develop Product Detail Page Template | F10: As soon as received | H10: 8 | I10: 0.5 | J10: High | K10: Yes | L10: Foundational elements from Design Delivery | M10: Not Started
A11: Public Web | B11: All | C11: All | D11: All | E11: Design and Develop Article Page Template | F11: As soon as received | H11: 3 | I11: 0.5 | J11: High | K11: Yes | L11: Foundational elements from Design Delivery | M11: Not Started
A12: Public Web | B12: All | C12: All | D12: All | E12: Design and Develop Hero Banner Component Updates | F12: As soon as received | H12: 4 | I12: 0.5 | J12: Medium | K12: Yes | L12: Foundational elements from Design Delivery | M12: Not Started
A13: Public Web | B13: All | C13: All | D13: All | E13: Design and Develop Landing page template | F13: As soon as received | H13: =NETWORKDAYS(F13,G13) -> #VALUE! | I13: 0.5 | J13: Medium | K13: Yes | L13: Foundational elements from Design Delivery | M13: Not Started
A14: Public Web | B14: All | C14: All | D14: All | E14: Design and Develop Section page template | F14: As soon as received | H14: =NETWORKDAYS(F14,G14) -> #VALUE! | I14: 0.5 | J14: Medium | K14: Yes | L14: Foundational elements from Design Delivery | M14: Not Started
A15: Public Web | B15: All | C15: All | D15: All | E15: Design and Develop Utility Template: Contact Us | F15: As soon as received | H15: =NETWORKDAYS(F15,G15) -> #VALUE! | I15: 0.5 | J15: Medium | K15: Yes | L15: Foundational elements from Design Delivery | M15: Not Started
A16: Public Web | B16: All | C16: All | D16: All | E16: Design and Develop Utility Template: All Calculators | F16: As soon as received | H16: =NETWORKDAYS(F16,G16) -> #VALUE! | I16: 0.5 | J16: Medium | K16: Yes | L16: Foundational elements from Design Delivery | M16: Not Started
A17: Public Web | B17: All | C17: All | D17: All | E17: Design and Develop Utility Template: Calculators Page | F17: As soon as received | H17: =NETWORKDAYS(F17,G17) -> #VALUE! | I17: 0.5 | J17: Medium | K17: Yes | L17: Foundational elements from Design Delivery | M17: Not Started
A18: Public Web | B18: All | C18: All | D18: All | E18: Design and Develop Utility Templates: About Us | F18: As soon as received | H18: =NETWORKDAYS(F18,G18) -> #VALUE! | I18: 0.5 | J18: Medium | K18: Yes | L18: Foundational elements from Design Delivery | M18: Not Started
A19: Public Web | B19: All | C19: All | D19: All | E19: Design and Develop Utility Template: Careers | F19: As soon as received | H19: =NETWORKDAYS(F19,G19) -> #VALUE! | I19: 0.5 | J19: Medium | K19: Yes | L19: Foundational elements from Design Delivery | M19: Not Started
A20: Public Web | B20: All | C20: All | D20: All | E20: Add copy standards to OMDS | F20: As soon as received | H20: =NETWORKDAYS(F20,G20) -> #VALUE! | I20: 0.5 | J20: Medium | K20: Yes | L20: Foundational elements from Design Delivery | M20: Not Started
A21: Secure Web | B21: All | C21: All | D21: All | E21: Add copy standards to OMDS | F21: As soon as received | H21: =NETWORKDAYS(F21,G21) -> #VALUE! | I21: 0.5 | J21: Medium | K21: Yes | L21: Foundational elements from Design Delivery | M21: Not Started
A22: Public Web | B22: All | C22: All | D22: All | E22: Design and Develop tenant template | F22: As soon as received | H22: =NETWORKDAYS(F22,G22) -> #VALUE! | I22: 0.5 | J22: Medium | K22: Yes | L22: Foundational elements from Design Delivery
A23: Secure Web | B23: All | C23: All | D23: All | E23: Design and Develop tenant template | F23: As soon as received | H23: =NETWORKDAYS(F23,G23) -> #VALUE! | I23: 0.5 | J23: Medium | K23: Yes | L23: Foundational elements from Design Delivery
H24: =NETWORKDAYS(F24,G24) -> 0
H25: =NETWORKDAYS(F25,G25) -> 0
H26: =NETWORKDAYS(F26,G26) -> 0
H27: =NETWORKDAYS(F27,G27) -> 0
H28: =NETWORKDAYS(F28,G28) -> 0
H29: =NETWORKDAYS(F29,G29) -> 0
H30: =NETWORKDAYS(F30,G30) -> 0
H31: =NETWORKDAYS(F31,G31) -> 0
H32: =NETWORKDAYS(F32,G32) -> 0
H33: =NETWORKDAYS(F33,G33) -> 0
H34: =NETWORKDAYS(F34,G34) -> 0
H35: =NETWORKDAYS(F35,G35) -> 0
... H141: =NETWORKDAYS(F141,G141) -> 0

Sheet Execution 
A1: Workstream: | B1: Execution
A2: Owner:
A3: Channel (i.e. Public or Secure Web) | B3: Domain (i.e. OMCOZA, OMCOM) | C3: Area/Journey (i.e. Personal, Business) | D3: Cluster (i.e. L&S, Wealth, Bank) | E3: Deliverable / Task / Milestone | F3: Start Date | G3: End Date | H3: Effort (in days) | I3: Confidence level to complete it in the number of days assigned? | J3: Priority | K3: Are your deliverable dependent on an upstream team to complete their work before you can begin? | L3: What deliverable are you dependent on? | M3: Current deliverable / task Status | N3: Comments
A4: Public Web | B4: OMCOM | C4: All | D4: OM | E4: Implement OMCOM into production | F4: 46181 | G4: 46185 | H4: =NETWORKDAYS(F4,G4) -> 5 | I4: 0.7 | J4: High | K4: Yes | L4: Stakeholder sign off | M4: In Progress | N4: Awaiting stakeholder approval
A5: Public Web | B5: OMCOZA, OMCOM, Bula-tsela, Malawi | C5: Entire site | E5: Dev: Co-locating Content & Analytics Tagging | F5: 46188 | G5: 46192 | H5: 5 | I5: 0.9 | J5: Critical | K5: No | M5: Not Started | N5: Creating new content_types and updating existing content_types in ContentStack
A6: Public Web | B6: OMCOZA, OMCOM, Bula-tsela, Malawi | C6: Entire site | E6: Dev: Applying Analytics Tracking to V2 Components | F6: 46196 | G6: 46203 | H6: 6 | I6: 0.7 | J6: Critical | K6: No | M6: Not Started | N6: Awaits co-location of Content with Analytics Tagging in ContentStack (where applicable)
A7: Public Web | B7: N/A | C7: N/A | E7: Dev: DevOps Quality Gate Pipeline | F7: 46188 | G7: 46192 | H7: 5 | I7: 0.7 | J7: High | K7: No | M7: Not Started
A8: Secure Web | B8: N/A | C8: N/A | E8: Dev: DevOps Quality Gate Pipeline | F8: 46195 | G8: 46202 | H8: 5 | I8: 0.7 | J8: High | K8: No | L8: N/A | M8: Not Started
A9: Public Web | B9: N/A | C9: N/A | E9: QE: Automated Testing Framework | F9: 46188 | G9: 46192 | H9: 5 | I9: 0.7 | J9: High | K9: No | L9: N/A | M9: Not Started
A10: Public Web | B10: N/A | C10: N/A | E10: Dev/QE: DevOps - Integrate Automated Testing | F10: 46195 | G10: 46202 | H10: 5 | I10: 0.6 | J10: High | K10: No | L10: N/A | M10: Not Started
A11: Secure Web | B11: N/A | C11: N/A | E11: QE: Automated Testing Framework | F11: 46195 | G11: 46202 | H11: 5 | I11: 0.7 | J11: High | K11: No | L11: N/A | M11: Not Started
A12: Secure Web | B12: N/A | C12: N/A | E12: Dev/QE: DevOps - Integrate Automated Testing | F12: 46202 | G12: 46206 | H12: 5 | I12: 0.6 | J12: High | K12: No | L12: N/A | M12: Not Started
A13: Public Web | B13: N/A | C13: N/A | E13: Dev: Observability Dashboard Templates for Sites | F13: 46188 | G13: 46195 | H13: 6 | I13: 0.7 | J13: Critical | K13: No | L13: N/A | M13: Not Started
A14: Secure Web | B14: N/A | C14: N/A | E14: Dev: Observability Dashboard Templates for Sites | F14: 46202 | G14: 46204 | H14: 3 | I14: 0.7 | J14: Critical | K14: Yes | L14: V2 DesignSystem update | M14: Not Started | N14: Awaiting update to current V2 DesignSystem to allow for different background color
A16: Public Web | F16: July Tasks from here
A18: Public Web | B18: All | C18: N/A | E18: Dev: Styling Backwards Compatibility - V2 ModularPage | F18: 46204 | G18: 46205 | H18: 2 | I18: 0.8 | J18: Critical | K18: Yes | L18: DesignSystem V2 Styling updates for background | M18: Not Started
A19: Public Web | B19: All | C19: N/A | E19: Dev: Styling Backwards Compatibility - V2 ArticleModularPage | F19: 46204 | G19: 46205 | H19: 2 | I19: 0.8 | J19: Critical | K19: Yes | L19: DesignSystem V2 Styling updates for background | M19: Not Started
A20: Public Web | B20: All | C20: N/A | E20: Dev: Export Analytics Data into Tableau | F20: 46204 | G20: 46209 | H20: ~5 | I20: 0.4 | J20: Critical | K20: No | M20: Not Started | N20: Requires understanding of data sources, data destination, access credentials to involved systems
A21: Secure Web | B21: N/A | C21: N/A | E21: Dev: Export Analytics Data into Tableau | F21: 46210 | G21: 46213 | H21: 3 | I21: 0.4 | J21: Critical | K21: No | M21: Not Started | N21: Requires understanding of data sources, data destination, access credentials to involved systems
A22: Public Web | B22: OMCOZA | C22: Entire site | E22: Dev: Configuring Web Transformation Page Template in ContentStack | F22: 46180 | G22: 46212 | H22: 4 | I22: 0.8 | J22: Critical | K22: Yes | L22: Web Transformation Page Template | M22: Not Started | N22: Requires at least Web Transformation Page Template red-zones
A23: Public Web | B23: OMCOZA | C23: Entire site | E23: Dev: Update Page Rendering Pipeline to support WT pages | F23: 46213 | G23: 46219 | H23: 5 | I23: 0.8 | J23: Critical | K23: Yes | L23: Web Transformation Page Template | M23: Not Started | N23: Requires at least Web Transformation Page Template red-zones
A24: Public Web | B24: OMCOZA | C24: N/A | E24: Dev: Navigation components updates public web | F24: TBC | H24: 8 | I24: 0.4 | J24: Critical | K24: Yes | L24: New Information Architecture for OMCOZA, New Transformation DesignSystem Nav component | M24: Not Started | N24: Awaiting completed Information Architecture, Awaiting new Transformation DesignSystem Nav component
A25: Public Web | B25: OMCOZA | C25: Personal | E25: QE : Automated Testing Framework (LS) | F25: TBC | H25: 8 | I25: 0.6 | J25: High | K25: No | L25: N/A | M25: Not Started
A26: Public Web | B26: OMCOZA | C26: Personal | E26: Dev :Observability Dashboards for various sites (LS) | H26: 5 | I26: 0.5 | J26: High | K26: No | L26: N/A | M26: Not Started
A27: Public Web | B27: OMCOZA | C27: Personal | F27: August Tasks from here
A28: Public Web | B28: OMCOZA | C28: Personal | E28: Dev : Modular Template (LS) | F28: TBC | H28: 3 | I28: 0.5 | J28: Critical | K28: Yes | L28: Design Page Template for Category & Product Detail pages | M28: Not Started | N28: Awaiting Page Template drop
A29: Public Web | B29: OMCOZA | C29: Personal | E29: Dev : Modular Page Components (LS) | F29: TBC | H29: ~5 | I29: 0.4 | J29: Critical | K29: Yes | L29: New Transformation DesignSystem components | M29: Not Started | N29: Awaiting new Transformation DesignSystem components. Uncertain on Effort in Days, quantity & complexity of components unknown.
A30: Public Web | B30: OMCOZA | C30: Personal | E30: Dev Applying analytics tracking to CMS (LS) | F30: TBC | H30: ~5 | I30: 0.4 | J30: Critical | K30: Yes | L30: New Transformation DesignSystem components | M30: Not Started | N30: Awaiting new Transformation DesignSystem components. Uncertain on Effort in Days, quantity & complexity of components unknown.
A31: Public Web | B31: OMCOZA | C31: Personal | E31: Dev: Omcoza -Licence cutover | F31: TBC | H31: 5 | I31: 0.6 | J31: Critical | K31: Yes | L31: Migrated OMCOZA site | M31: Not Started
A32: Public Web | B32: OMCOZA | C32: Personal | E32: Dev : Tableu Analytics | F32: TBC | H32: 8 | I32: 0.5 | J32: Critical | K32: No | L32: N/A | M32: Not Started
C34: OTHER STREAMS | H34: =NETWORKDAYS(F34,G34) -> 0
C35: OTHER AREAS | H35: =NETWORKDAYS(F35,G35) -> 0
C36: SECURE | H36: =NETWORKDAYS(F36,G36) -> 0
H37: =NETWORKDAYS(F37,G37) -> 0
H38: =NETWORKDAYS(F38,G38) -> 0
H39: =NETWORKDAYS(F39,G39) -> 0
H40: =NETWORKDAYS(F40,G40) -> 0
H41: =NETWORKDAYS(F41,G41) -> 0
H42: =NETWORKDAYS(F42,G42) -> 0
H43: =NETWORKDAYS(F43,G43) -> 0
...

Sheet Publishing
A1: Workstream: | B1: Publishing
A2: Owner: | B2: Bernice
A3: Channel (i.e. Public or Secure Web) | B3: Domain (i.e. OMCOZA, OMCOM) | C3: Area/Journey (i.e. Personal, Business) | D3: Cluster (i.e. L&S, Wealth, Bank) | E3: Deliverable / Task / Milestone | F3: Start Date | G3: End Date | H3: Effort (in days) | I3: Confidence level to complete it in the number of days assigned? | J3: Priority | K3: Are your deliverable dependent on an upstream team to complete their work before you can begin? | L3: What deliverable are you dependent on? | M3: Current deliverable / task Status | N3: Comments
A4: Public Web | B4: OMCOM | C4: Entire site | E4: Take live in V2 new platform | F4: 46182 | G4: 46184 | H4: =NETWORKDAYS(F4,G4) -> 3 | I4: 0.8 | J4: High | K4: No | M4: N/A
A5: Public Web | B5: OMAI (Alternatives) | C5: Entire site | E5: Testing in V2 new platform and log bugs | F5: 46184 | G5: 46199 | H5: =NETWORKDAYS(F5,G5) -> 12 | I5: 1 | J5: High | K5: No | M5: Not Started | N5: Need to work with Web developers for bug fixes
A6: Public Web | B6: OMAI (Alternatives) | C6: Entire site | E6: Take live in V2 new platform | F6: JULY - TBC | H6: =NETWORKDAYS(F6,G6) -> #VALUE! | I6: 0.8 | J6: High | K6: No | M6: N/A | N6: Go live date will be determined in the next PI Planning
A7: Public Web | B7: OMCOZA | C7: Personal | D7: Funeral | E7: Record Funeral URL structure based on proposed sunset/consolidated pages. | F7: 46183 | G7: 46191 | H7: =NETWORKDAYS(F7,G7) -> 7 | I7: 0.9 | J7: High | K7: No | M7: Not Started | N7: Work with Justin on the urls for this section
A8: Public Web | B8: OMCOZA | C8: Personal | D8: Retirement | E8: Record Retirement URL structure based on consolidated pages as per new IA. | F8: 46183 | G8: 46191 | H8: =NETWORKDAYS(F8,G8) -> 7 | I8: 0.9 | J8: High | K8: No | M8: Not Started | N8: Work with Justin on the urls for this section
A9: Public Web | B9: OMCOZA | C9: Personal | D9: Flexi Save | E9: Record Flexi Save URL structure based on consolidated pages as per new IA. | F9: 46183 | G9: 46191 | H9: =NETWORKDAYS(F9,G9) -> 7 | I9: 0.9 | J9: High | K9: No | M9: Not Started | N9: Work with Justin on the urls for this section
A10: Public Web | B10: OMCOZA | C10: As is pages | E10: Record url structure based on all AS is pages (keep/remove/consolidate) | I10: 0.7 | J10: High | K10: Yes | L10: Design/content | M10: Not Started
A11: Public Web | B11: OMCOZA | C11: As is pages | E11: Start moving as is pages over to Beta | F11: 46204 | G11: 46357 | H11: =NETWORKDAYS(F11,G11) -> 110 | I11: 0.8 | J11: High | K11: Yes | L11: Design | M11: In Progress | N11: Confirm pages and urls for "as is" pages before I can start moving
A12: Public Web | B12: OMCOZA | C12: Personal | E12: Record url structure for all remaining Personal pages (keep/remove/consolidate) | F12: 46233 | I12: 0.7 | J12: High | K12: Yes | L12: Design/content | M12: Not Started
A13: Public Web | B13: OMCOZA | C13: Personal | E13: Start building new template pages | F13: 46233 | G13: 46357 | H13: =NETWORKDAYS(F13,G13) -> 89 | I13: 0.7 | J13: High | K13: Yes | L13: Design / Design Systems / Development | M13: Not Started | N13: Work can only begin once all upstream teams have completed their work
A14: Public Web | B14: OMCOZA | C14: Corporate | E14: Record url structure for all remaining Corporate pages (keep/remove/consolidate) | F14: 46235 | I14: 0.7 | J14: High | K14: Yes | L14: Design/content | M14: Not Started
A15: Public Web | B15: OMCOZA | C15: Corporate | E15: Start building new template pages | F15: 46235 | G15: 46357 | H15: =NETWORKDAYS(F15,G15) -> 87 | I15: 0.4 | J15: High | K15: Yes | L15: Design / Design Systems / Development | M15: Not Started | N15: Work can only begin once all upstream teams have completed their work
A16: Public Web | B16: OMCOZA | C16: Wealth | E16: Start building new template pages | F16: 46235 | G16: 46358 | H16: =NETWORKDAYS(F16,G16) -> 88 | I16: 0.3 | J16: High | K16: Yes | L16: Design / Design Systems / Development | M16: Not Started | N16: Work can only begin once all upstream teams have completed their work
A17: Public Web | B17: OMCOZA | C17: Utility pages | E17: Record url structure for all remaining Utility pages (keep/remove/consolidate) | F17: 46235 | I17: 0.7 | J17: High | K17: Yes | L17: Design/content | M17: Not Started
A18: Public Web | B18: OMCOZA | C18: Utility pages | E18: Start building new template pages | F18: 46235 | G18: 46359 | H18: =NETWORKDAYS(F18,G18) -> 89 | I18: 0.3 | J18: High | K18: Yes | L18: Design / Design Systems / Development | M18: Not Started | N18: Work can only begin once all upstream teams have completed their work
A19: Public Web | B19: OMCOZA | C19: About Us | E19: Record url structure for all remaining About us pages (keep/remove/consolidate) | F19: 46235 | I19: 0.7 | J19: High | K19: Yes | L19: Design/content | M19: Not Started
A20: Public Web | B20: OMCOZA | C20: About us | E20: Start building new template pages | F20: 46235 | G20: 46360 | H20: =NETWORKDAYS(F20,G20) -> 90 | I20: 0.3 | J20: High | K20: Yes | L20: Design / Design Systems / Development | M20: Not Started | N20: Work can only begin once all upstream teams have completed their work
A21: Public Web | B21: OMCOZA | C21: Careers | E21: Record url structure for all remaining Careers pages (keep/remove/consolidate) | F21: 46235 | I21: 0.7 | J21: High | K21: Yes | L21: Design/content | M21: Not Started
A22: Public Web | B22: OMCOZA | C22: Careers | E22: Start building new template pages | F22: 46235 | G22: 46361 | H22: =NETWORKDAYS(F22,G22) -> 90 | I22: 0.3 | J22: High | K22: Yes | L22: Design / Design Systems / Development | M22: Not Started | N22: Work can only begin once all upstream teams have completed their work
A23: Public Web | B23: OMCOZA | C23: Business | E23: Record url structure for all remaining Business pages (keep/remove/consolidate) | F23: 46235 | I23: 0.7 | J23: High | K23: Yes | L23: Design/content | M23: Not Started
A24: Public Web | B24: OMCOZA | C24: Business | E24: Start building new template pages | F24: 46235 | G24: 46362 | H24: =NETWORKDAYS(F24,G24) -> 90 | I24: 0.3 | J24: High | K24: Yes | L24: Design / Design Systems / Development | M24: Not Started | N24: Work can only begin once all upstream teams have completed their work
A25: Public Web | B25: OMCOM | E25: Add new Nav, Footer and update IA | F25: 46235 | G25: 46362 | H25: =NETWORKDAYS(F25,G25) -> 90 | I25: 0.5 | J25: Medium | K25: Yes | L25: Design / Design Systems / Development | M25: Not Started | N25: Work can only begin once all upstream teams have completed their work
A26: Public Web | B26: OMAI (Alternatives) | E26: Add new Nav, Footer and update IA | F26: 46235 | G26: 46362 | H26: =NETWORKDAYS(F26,G26) -> 90 | I26: 0.5 | J26: Medium | K26: Yes | L26: Design / Design Systems / Development | M26: Not Started | N26: Work can only begin once all upstream teams have completed their work
A27: Public Web | B27: Bula Tsela | E27: Add new Nav, Footer and update IA | F27: 46235 | G27: 46362 | H27: =NETWORKDAYS(F27,G27) -> 90 | I27: 0.5 | J27: Medium | K27: Yes | L27: Design / Design Systems / Development | M27: Not Started | N27: Work can only begin once all upstream teams have completed their work
A28: Public Web | B28: LTD | E28: Add new Nav, Footer and update IA | F28: 46235 | G28: 46362 | H28: =NETWORKDAYS(F28,G28) -> 90 | I28: 0.5 | J28: Medium | K28: Yes | L28: Design / Design Systems / Development | M28: Not Started | N28: Work can only begin once all upstream teams have completed their work
A29: Public Web | B29: OMAR | E29: Publishing requirements for OMAR, logged on OMAR tab | F29: 46235 | G29: 46362 | H29: =NETWORKDAYS(F29,G29) -> 90 | I29: 0.1 | J29: Medium | K29: Yes | L29: Design / Design Systems / Development | M29: Not Started | N29: Engagement with OMAR teams is required in order to determine who will be responsible for the publishing work. Work can only begin once all upstream teams have completed their work. This is also recorded in more detail in the OMAR tab.
A30: Public Web | B30: OMCOZA | C30: Entire site | D30: Entire site | E30: Add all new redirects for the site | F30: TBC | G30: TBC | H30: TBC | L30: n/a | M30: Not Started | N30: Redirect entry needs to be added for all urls that were changed. This can only be added once the new site is live.
H32: =NETWORKDAYS(F32,G32) -> 0
H33: =NETWORKDAYS(F33,G33) -> 0
H34: =NETWORKDAYS(F34,G34) -> 0
H35: =NETWORKDAYS(F35,G35) -> 0
H36: =NETWORKDAYS(F36,G36) -> 0
H37: =NETWORKDAYS(F37,G37) -> 0
H38: =NETWORKDAYS(F38,G38) -> 0
H39: =NETWORKDAYS(F39,G39) -> 0
H40: =NETWORKDAYS(F40,G40) -> 0
H41: =NETWORKDAYS(F41,G41) -> 0
...

Sheet Go-Live Readiness
A1: Workstream: | B1: Go-Live Readiness
A2: Owner:
A3: Channel (i.e. Public or Secure Web) | B3: Domain (i.e. OMCOZA, OMCOM) | C3: Area/Journey (i.e. Personal, Business) | D3: Cluster (i.e. L&S, Wealth, Bank) | E3: Deliverable / Task / Milestone | F3: Start Date | G3: End Date | H3: Effort (in days) | I3: Confidence level to complete it in the number of days assigned? | J3: Priority | K3: Are your deliverable dependent on an upstream team to complete their work before you can begin? | L3: What deliverable are you dependent on? | M3: Current deliverable / task Status | N3: Comments
A4: Public Web | B4: All | C4: All | D4: All | E4: Penetration Testing Discussion and confirmation | F4: 46177 | G4: 46177 | H4: =NETWORKDAYS(F4,G4) -> 1 | I4: 1 | J4: High | K4: No | L4: Nothing a discussion point | M4: Complete | N4: Penetration Testing has to be done, at no cost to us, we just have to send URL' for testing - URL of sites must be sent Security Team
A5: Public Web | B5: All | C5: All | D5: All | E5: Qaulity Assurance Approval | F5: 46327 | G5: 46356 | H5: =NETWORKDAYS(F5,G5) -> 21 | I5: 1 | J5: Low | K5: No | L5: Nothing a discussion point | M5: Not Started
A6: Public Web | B6: All | C6: All | D6: All | E6: Security Approvals | F6: 46327 | G6: 46356 | H6: =NETWORKDAYS(F6,G6) -> 21 | I6: 1 | J6: Low | K6: Yes | L6: All deliveries must be in QA State
A7: Public Web | B7: All | C7: All | D7: All | E7: Internal Communication ( Call Centre) - Marketing Team Driven | F7: 46266 | G7: 46356 | H7: =NETWORKDAYS(F7,G7) -> 65 | I7: 0.7 | J7: Low | K7: Yes | L7: All deliveries must be in readiness state for Comms to be reviewed and sent to internal team and External T | M7: Not Started
A8: Public Web | B8: All | C8: All | D8: All | E8: Service Now Update | F8: 46266 | G8: 46356 | H8: =NETWORKDAYS(F8,G8) -> 65 | I8: 0.8 | J8: Low | K8: No | L8: Nothing a discussion point | M8: Not Started
A9: Public Web | B9: All | C9: All | D9: All | E9: Executive Approval | F9: 46342 | G9: 46356 | H9: =NETWORKDAYS(F9,G9) -> 11 | I9: 0.5 | J9: Low | K9: Yes | L9: Approval to go ahead from all other Teams | M9: Not Started
A10: Public Web | B10: All | C10: All | D10: All | E10: Change Management Go Ahead | F10: 46355 | G10: 46356 | H10: =NETWORKDAYS(F10,G10) -> 1 | I10: 0.5 | J10: Low | K10: Yes | L10: All work by teams must be completed | M10: Not Started
A11: Public Web | B11: All | C11: All | D11: All | E11: Customer Expirience Tool | F11: 46177 | G11: 46295 | H11: =NETWORKDAYS(F11,G11) -> 85 | I11: 0.1 | J11: Low | K11: Yes | L11: Tool Evaluating | M11: Not Started | N11: Tool still in evaluation tool
H12: =NETWORKDAYS(F12,G12) -> 0
H13: =NETWORKDAYS(F13,G13) -> 0
H14: =NETWORKDAYS(F14,G14) -> 0
H15: =NETWORKDAYS(F15,G15) -> 0
H16: =NETWORKDAYS(F16,G16) -> 0
H17: =NETWORKDAYS(F17,G17) -> 0
H18: =NETWORKDAYS(F18,G18) -> 0
H19: =NETWORKDAYS(F19,G19) -> 0
H20: =NETWORKDAYS(F20,G20) -> 0
H21: =NETWORKDAYS(F21,G21) -> 0
H22: =NETWORKDAYS(F22,G22) -> 0
H23: =NETWORKDAYS(F23,G23) -> 0
... H138: =NETWORKDAYS(F138,G138) -> 0

Sheet  SEO Analytics 
A1: Workstream: | B1: SEO / Analytics
A2: Owner:
A3: Channel (i.e. Public or Secure Web) | B3: Domain (i.e. OMCOZA, OMCOM) | C3: Area/Journey (i.e. Personal, Business) | D3: Cluster (i.e. L&S, Wealth, Bank) | E3: Deliverable / Task / Milestone | F3: Start Date | G3: End Date | H3: Effort (in days) | I3: Confidence level to complete it in the number of days assigned? | J3: Priority | K3: Are your deliverable dependent on an upstream team to complete their work before you can begin? | L3: What deliverable are you dependent on? | M3: Current deliverable / task Status | N3: Comments
A4: Public Web | B4: All | C4: All | D4: All | E4: Confirm Engagment Cycle with SEO Team | F4: 46181 | G4: 46188 | H4: =NETWORKDAYS(F4,G4) -> 6 | I4: 1 | J4: High | K4: No | L4: None | M4: In Progress | N4: Final Approval will be provided by the CMO
A5: Public Web | B5: All | C5: All | D5: All | E5: SEO Requirements to Dev Team | F5: 46181 | G5: 46188 | H5: =NETWORKDAYS(F5,G5) -> 6 | I5: 1 | J5: High | K5: No
H6: =NETWORKDAYS(F6,G6) -> 0
H7: =NETWORKDAYS(F7,G7) -> 0
H8: =NETWORKDAYS(F8,G8) -> 0
H9: =NETWORKDAYS(F9,G9) -> 0
H10: =NETWORKDAYS(F10,G10) -> 0
H11: =NETWORKDAYS(F11,G11) -> 0
H12: =NETWORKDAYS(F12,G12) -> 0
H13: =NETWORKDAYS(F13,G13) -> 0
H14: =NETWORKDAYS(F14,G14) -> 0
H15: =NETWORKDAYS(F15,G15) -> 0
H16: =NETWORKDAYS(F16,G16) -> 0
H17: =NETWORKDAYS(F17,G17) -> 0
... H140: =NETWORKDAYS(F140,G140) -> 0

Sheet OMAR
A1: OMA | B1: OMAR
A2: Owner:
A3: Channel (i.e. Public or Secure Web) | B3: Domain (i.e. OMCOZA, OMCOM) | C3: Area/Journey (i.e. Personal, Business) | D3: Cluster (i.e. L&S, Wealth, Bank) | E3: Deliverable / Task / Milestone | F3: Start Date | G3: End Date | H3: Effort (in days) | I3: Confidence level to complete it in the number of days assigned? | J3: Priority | K3: Are your deliverable dependent on an upstream team to complete their work before you can begin? | L3: What deliverable are you dependent on? | M3: Current deliverable / task Status | N3: Comments
A4: Public Web | B4: OMAR | C4: OMAR | D4: OMAR | E4: Engagement required to communicate recalibration of project to various OMAR Stakeholder | F4: 46181 | G4: 46203 | H4: =NETWORKDAYS(F4,G4) -> 17 | I4: 0.7 | J4: Critical | K4: No | L4: Nothing , we need a clears comms plan for OMAR | M4: In Progress | N4: Engagement with OMAR teams are required in order to assist them with the recalibration of their plans, the plan must take into account Navigation and plan changes
A5: Public Web | B5: Botswana | C5: Botswana | D5: Botswana | E5: Publishing of all pages in V2 New platform | F5: TBC | G5: TBC | H5: TBC | I5: 0.1 | J5: High | K5: Yes | L5: Design / Design Systems / Development | M5: Not Started | N5: Engagement with OMAR teams is required in order to determine who will be responsible for the publishing work. Work can only begin once all upstream teams have completed their work
A6: Public Web | B6: Ghana | C6: Ghana | D6: Ghana | E6: Publishing of all pages in V2 New platform | F6: TBC | G6: TBC | H6: TBC | I6: 0.1 | J6: High | K6: Yes | L6: Design / Design Systems / Development | M6: Not Started | N6: Engagement with OMAR teams is required in order to determine who will be responsible for the publishing work. Work can only begin once all upstream teams have completed their work
A7: Public Web | B7: Kenya | C7: Kenya | D7: Kenya | E7: Publishing of all pages in V2 New platform | F7: TBC | G7: TBC | H7: TBC | I7: 0.1 | J7: High | K7: Yes | L7: Design / Design Systems / Development | M7: Not Started | N7: Engagement with OMAR teams is required in order to determine who will be responsible for the publishing work. Work can only begin once all upstream teams have completed their work
A8: Public Web | B8: Namibia | C8: Namibia | D8: Namibia | E8: Publishing of all pages in V2 New platform | F8: TBC | G8: TBC | H8: TBC | I8: 0.1 | J8: High | K8: Yes | L8: Design / Design Systems / Development | M8: Not Started | N8: Engagement with OMAR teams is required in order to determine who will be responsible for the publishing work. Work can only begin once all upstream teams have completed their work
